<?xml version='1.0'?>
<sdf version='1.3'>
  <model name="volksbot">
  <static>false</static>

<!-- CHASSIS -->  
  <link name='chassis'>
    <pose>0 0 .1 0 0 0</pose>
    <collision name='collision'>
        <geometry>
            <box>
                <size>.4 .2 .1</size>
            </box>
        </geometry>
    </collision>
    <visual name='visual'>
        <geometry>
            <box>
                <size>.4 .2 .1</size>
            </box>
        </geometry>
    </visual>
    </link>     
  
  <!-- LEFT back Wheel -->
    <link name="left_back_wheel">
        <pose>0.15 0.11 0.05 0 1.5707 1.5707</pose>
        <collision name="collision">
            <geometry>
                <cylinder>
                    <radius>.05</radius>
                    <length>.025</length>
                </cylinder>
            </geometry>
        </collision>
        <visual name="visual">
            <geometry>
                <cylinder>
                    <radius>.05</radius>
                    <length>.025</length>
                </cylinder>
            </geometry>
        </visual>
    </link>
    
    <!-- LEFT front Wheel -->
    <link name="left_front_wheel">
        <pose>-0.15 0.11 0.05 0 1.5707 1.5707</pose>
        <collision name="collision">
            <geometry>
                <cylinder>
                    <radius>.05</radius>
                    <length>.025</length>
                </cylinder>
            </geometry>
        </collision>
        <visual name="visual">
            <geometry>
                <cylinder>
                    <radius>.05</radius>
                    <length>.025</length>
                </cylinder>
            </geometry>
        </visual>
    </link>
  
    <!-- RIGHT back Wheel -->
    <link name="right_back_wheel">
        <pose>0.15 -0.11 0.05 0 1.5707 1.5707</pose>
        <collision name="collision">
            <geometry>
                <cylinder>
                    <radius>.05</radius>
                    <length>.025</length>
                </cylinder>
            </geometry>
        </collision>
        <visual name="visual">
            <geometry>
                <cylinder>
                    <radius>.05</radius>
                    <length>.025</length>
                </cylinder>
            </geometry>
        </visual>
    </link>
    
    <!-- RIGHT front Wheel -->
    <link name="right_front_wheel">
        <pose>-0.15 -0.11 0.05 0 1.5707 1.5707</pose>
        <collision name="collision">
            <geometry>
                <cylinder>
                    <radius>.05</radius>
                    <length>.025</length>
                </cylinder>
            </geometry>
        </collision>
        <visual name="visual">
            <geometry>
                <cylinder>
                    <radius>.05</radius>
                    <length>.025</length>
                </cylinder>
            </geometry>
        </visual>
    </link>

  <!-- LEFT back Wheel Chassis joint -->
    <joint type="revolute" name="left_back_wheel_hinge">
        <pose>0 0 -0.03 0 0 0</pose>
        <child>left_back_wheel</child>
        <parent>chassis</parent>
        <axis>
            <xyz>0 1 0</xyz>
        </axis>
    </joint>
    
    <!-- LEFT front Wheel Chassis joint -->
    <joint type="revolute" name="left_front_wheel_hinge">
        <pose>0 0 -0.03 0 0 0</pose>
        <child>left_front_wheel</child>
        <parent>chassis</parent>
        <axis>
            <xyz>0 1 0</xyz>
        </axis>
    </joint>

<!-- RIGHT Wheel Chassis joint -->
    <joint type="revolute" name="right_back_wheel_hinge">
        <pose>0 0 0.03 0 0 0</pose>
        <child>right_back_wheel</child>
        <parent>chassis</parent>
        <axis>
            <xyz>0 1 0</xyz>
        </axis>
  </joint>
  
  <joint type="revolute" name="right_front_wheel_hinge">
    <pose>0 0 0.03 0 0 0</pose>
    <child>right_front_wheel</child>
    <parent>chassis</parent>
    <axis>
        <xyz>0 1 0</xyz>
    </axis>
  </joint>
  
  </model>
</sdf>
