<?xml version="1.0"?>
<robot name="Volksbot"
	xmlns:xi="http://www.w3.org/2001/XInclude"
	xmlns:gazebo="http://playerstage.sourceforge.net/gazebo/xmlschema/#gz"
	xmlns:model="http://playerstage.sourceforge.net/gazebo/xmlschema/#model"
	xmlns:sensor="http://playerstage.sourceforge.net/gazebo/xmlschema/#sensor"
	xmlns:body="http://playerstage.sourceforge.net/gazebo/xmlschema/#body"
	xmlns:geom="http://playerstage.sourceforge.net/gazebo/xmlschema/#geom"
	xmlns:joint="http://playerstage.sourceforge.net/gazebo/xmlschema/#joint"
	xmlns:controller="http://playerstage.sourceforge.net/gazebo/xmlschema/#controller"
	xmlns:interface="http://playerstage.sourceforge.net/gazebo/xmlschema/#interface"
	xmlns:rendering="http://playerstage.sourceforge.net/gazebo/xmlschema/#rendering"
	xmlns:renderable="http://playerstage.sourceforge.net/gazebo/xmlschema/#renderable"
	xmlns:physics="http://playerstage.sourceforge.net/gazebo/xmlschema/#physics"
	xmlns:xacro="http://ros.org/wiki/xacro"
>

<!--Variable Pi definieren-->
<property name="pi" value="3.1415926535897931"/>
<property name="mass_base" value="25"/>     <!-- alter Wert 25 -->
<property name="mass_wheel" value="0.85"/>  <!-- alter Wert 0.75 -->

<!-- ######################  base_footprint  #######################################################
 its a fictitious link(frame) that is on the ground right below base_link origin, navigation stack depends on this frame-->
	<link name="base_footprint">
		<visual>
			<geometry>
				<box size="0.001 0.001 0.001"/>				
			</geometry>
			<origin rpy="0 0 0" xyz="0 0 0"/>
		</visual>
<!--		<collision>
			<geometry>
				<box size="0.001 0.001 0.001"/>
			</geometry>
			<origin xyz="0 0 0"/>
		</collision>
		<inertial>
			<mass value="0.0001"/>
			<inertia ixx="0.0001" ixy="0.0" ixz="0.0" iyy="0.0001" iyz="0.0" izz="0.0001"/>
			<origin xyz="0 0 0.0" />
		</inertial>  -->
	</link>
	<joint name="base_footprint_joint" type="fixed">
		<parent link="base_footprint"/>
		<child link="base_link"/>
		<origin rpy="0 0 0" xyz="0 0 0"/>
	</joint>
	
<!-- #######################  Main Body  ###################################-->	
	<link name="base_link">
		<visual>
			<geometry>
				<mesh filename="package://volksbot_new/Media/VolksbotChassis.stl"/>
			</geometry>
			<origin rpy="0 0 0" xyz="0 0 0.175"/>
			<material name="light_gray_one">
				<color rgba="0.93 0.91 0.91 1"/>
			</material>
		</visual>
		<collision>
			<geometry>
				<mesh filename="package://volksbot_new/Media/VolksbotChassis.stl"/>
			</geometry>
			<origin xyz="0 0 0.175"/>
		</collision>
		<inertial>
			<mass value="${mass_base}"/>
			<inertia ixx="0.83333" ixy="0.0" ixz="0.0" iyy="1.0052" iyz="0.0" izz="0.33854"/>
			<origin xyz="0 0 0.075" />
		</inertial>
	</link>
	<gazebo reference="base_link">
		<material>Gazebo/WhiteGlow</material>
		<turnGravityOff>false</turnGravityOff>
	</gazebo>
<!-- #######################  Frontplatte  ###################################-->	
	<link name="frontpanel_link">
		<visual>
			<geometry>
				<mesh filename="package://volksbot_new/Media/VolksbotFrontplatte.stl"/>
			</geometry>
			<origin rpy="0 0 0" xyz="-0.002 0 0.075"/>
			<material name="gray">
				<color rgba="0.36 .36 .36 1"/>
			</material>
		</visual>
		<collision>
			<geometry>
				<mesh filename="package://volksbot_new/Media/VolksbotFrontplatte.stl"/>
			</geometry>
			<origin xyz="-0.002 0 0.075"/>
		</collision> 
		<inertial>
			<mass value="0.01"/>
			<inertia ixx="0.0001" ixy="0.0" ixz="0.0" iyy="0.0001" iyz="0.0" izz="0.0001"/>
			<origin xyz="-0.17 0 -0.025" />
		</inertial> 
	</link>
	<joint name="frontpanel_joint" type="fixed">
		<parent link="base_link"/>
		<child link="frontpanel_link"/>
		<origin rpy="0 0 0" xyz="0.17 0 0.1"/>
	</joint>

	<gazebo reference="frontpanel_link">
		<material>Gazebo/Black</material>
		<turnGravityOff>false</turnGravityOff>
	</gazebo>
<!-- #######################  Laserstange  ###################################-->	
	<link name="laserstick_link">
		<visual>
			<geometry>
				<mesh filename="package://volksbot_new/Media/VolksbotLaserstange.stl"/>
			</geometry>
			<origin rpy="0 0 0" xyz="0 0 0"/>
			<material name="light_gray_one">
				<color rgba="0.93 0.91 0.91 1"/>
			</material>
		</visual>
		<collision>
			<geometry>
				<mesh filename="package://volksbot_new/Media/VolksbotLaserstange.stl"/>
			</geometry>
			<origin xyz="0 0 0"/>
		</collision> 
		<inertial>
			<mass value="0.01"/>
			<inertia ixx="0.0001" ixy="0.0" ixz="0.0" iyy="0.0001" iyz="0.0" izz="0.0001"/>
			<origin xyz="0 0 -0.175" />
		</inertial> 
	</link>
	<joint name="laserstick_joint" type="fixed">
		<parent link="base_link"/>
		<child link="laserstick_link"/>
		<origin rpy="0 0 0" xyz="0 0 0.25"/>
	</joint>

	<gazebo reference="laserstick_link">
		<material>Gazebo/WhiteGlow</material>
		<turnGravityOff>false</turnGravityOff>
	</gazebo>

<!-- #######################  Pc  ###################################-->	
	<link name="pc_link">
		<visual>
			<geometry>
				<mesh filename="package://volksbot_new/Media/VolksbotPc.stl"/>
			</geometry>
			<origin rpy="0 0 0" xyz="-0.05 0 0"/>
			<material name="dark_gray">
				<color rgba="0.11 .11 .11 1"/>
			</material>
		</visual>
		<collision>
			<geometry>
				<mesh filename="package://volksbot_new/Media/VolksbotPc.stl"/>
			</geometry>
			<origin xyz="-0.05 0 0"/>
		</collision> 
		<inertial>
			<mass value="0.01"/>
			<inertia ixx="0.0001" ixy="0.0" ixz="0.0" iyy="0.0001" iyz="0.0" izz="0.0001"/>
			<origin xyz="-0.05 0 -0.175" />
		</inertial> 
	</link>
	<joint name="pc_joint" type="fixed">
		<parent link="base_link"/>
		<child link="pc_link"/>
		<origin rpy="0 0 0" xyz="0.05 0 0.25"/>
	</joint>
	<gazebo reference="pc_link">
		<material>Gazebo/Black</material>
		<turnGravityOff>false</turnGravityOff>
	</gazebo>

<!-- #######################  Motor&Kette  ###################################-->	
	<link name="motor_link">
		<visual>
			<geometry>
				<mesh filename="package://volksbot_new/Media/VolksbotAntrieb.stl"/>
			</geometry>
			<origin rpy="0 0 0" xyz="0 0 0"/>
			<material name="another_gray">
				<color rgba="0.65 .65 .65 1"/>
			</material>
		</visual>
		<collision>
			<geometry>
				<mesh filename="package://volksbot_new/Media/VolksbotAntrieb.stl"/>
			</geometry>
			<origin xyz="0 0 0"/>
		</collision> 
		<inertial>
			<mass value="0.01"/>
			<inertia ixx="0.0001" ixy="0.0" ixz="0.0" iyy="0.0001" iyz="0.0" izz="0.0001"/>
			<origin xyz="0 0 -0.055" />
		</inertial> 
	</link>
	<joint name="motor_joint" type="fixed">
		<parent link="base_link"/>
		<child link="motor_link"/>
		<origin rpy="0 0 0" xyz="0 0 0.13"/>
	</joint>
	<gazebo reference="motor_link">
		<material>Gazebo/BlueGlow</material>
		<turnGravityOff>false</turnGravityOff>
	</gazebo>
<!-- #######################  Battery  ###################################-->	
	<link name="battery_link">
		<visual>
			<geometry>
				<mesh filename="package://volksbot_new/Media/VolksbotBattery.stl"/>
			</geometry>
			<origin rpy="0 0 0" xyz="0 0 0"/>
			<material name="battery_gray">
				<color rgba=".07 .07 .07 1"/>
			</material>
		</visual>
		<collision>
			<geometry>
				<mesh filename="package://volksbot_new/Media/VolksbotBattery.stl"/>
			</geometry>
			<origin xyz="0 0 0"/>
		</collision>
		<inertial>
			<mass value="0.01"/>
			<inertia ixx="0.0001" ixy="0.0" ixz="0.0" iyy="0.0001" iyz="0.0" izz="0.0001"/>
			<origin xyz="0 0 -0.025" />
		</inertial> 
	</link>
	<joint name="battery_joint" type="fixed">
		<parent link="base_link"/>
		<child link="battery_link"/>
		<origin rpy="0 0 0" xyz="0 0 0.1"/>
	</joint>
	<gazebo reference="battery_link">
		<material>Gazebo/Black</material>
		<turnGravityOff>false</turnGravityOff>
	</gazebo>
<!--  ##############################  Rad vorne Rechts  ##############################-->	
	<link name="right_front_wheel">
		<visual>
			<geometry>
				<mesh filename="package://volksbot_new/Media/original5.stl"/>			
			</geometry>
			<origin rpy="${pi/2} 0 0" xyz="0 0 0"/>
			<material name="black">
				<color rgba="0.1 0.1 0.1 1"/>
			</material>
		</visual>
		<collision>
			<geometry>
				<cylinder length="0.085" radius="0.13"/>
			</geometry>
			<origin rpy="${pi/2} 0 0" xyz="0 0 0"/>
		</collision>
		<inertial>
			<mass value="${mass_wheel}"/>
			<inertia ixx="0.0041" ixy="0.0" ixz="0.0" iyy="0.0041" iyz="0.0" izz="0.00718"/>
			<origin xyz="0 0 0" />
		</inertial>
	</link>

	<joint name="right_front_wheel_joint" type="continuous">
		<axis xyz="0 1 0"/>
		<parent link="base_link"/>
		<child link="right_front_wheel"/>
		<origin rpy="0 0 0" xyz="0.14 -0.2075 0.13"/>
		<limit effort="100" velocity="100"/>
		<dynamics damping="0.0" friction="0.0"/>
	</joint>
	<gazebo reference="right_front_wheel">
		<mu1 value="100"/>   <!--100-->
		<mu2 value="100"/>   <!--100-->
		<kp value="1000000.0"/> <!--100000000.0-->
		<kd value="10000.0"/>    <!--10000.0 -->
		<fdir value="1 0 0"/> 
		<friction value="100.0"/>  
		<material>Gazebo/Grey</material>
		<turnGravityOff>false</turnGravityOff>
	</gazebo>

<!--  ###############################  Rad hinten Rechts  ########################################## -->		
	<link name="right_back_wheel">
		<visual>
			<geometry>
				<mesh filename="package://volksbot_new/Media/original5.stl"/>			
			</geometry>
			<origin rpy="${pi/2} 0 0" xyz="0 0 0"/>
			<material name="black">
				<color rgba="0.1 0.1 0.1 1"/>
			</material>
		</visual>
		<collision>
			<geometry>
				<cylinder length="0.085" radius="0.13"/>
			</geometry>
			<origin rpy="${pi/2} 0 0" xyz="0 0 0"/>
		</collision>
		<inertial>
			<mass value="${mass_wheel}"/>
			<inertia ixx="0.0041" ixy="0.0" ixz="0.0" iyy="0.0041" iyz="0.0" izz="0.00718"/>
			<origin xyz="0 0 0" />
		</inertial>
	</link>

	<joint name="right_back_wheel_joint" type="continuous">
		<axis xyz="0 1 0"/>
		<parent link="base_link"/>
		<child link="right_back_wheel"/>
		<origin rpy="0 0 0" xyz="-0.14 -0.2075 0.13"/>
		<limit effort="100" velocity="100"/>
		<dynamics damping="0.0" friction="0.0"/>
	</joint>
	<gazebo reference="right_back_wheel">
		<mu1 value="100"/> 
		<mu2 value="100"/>
		<kp value="1000000.0"/>  
		<kd value="10000.0"/>    
		<fdir value="1 0 0"/>
		<friction value="100.0"/>   
		<material>Gazebo/Grey</material>
		<turnGravityOff>false</turnGravityOff>
	</gazebo>

<!--  ####################################  Rad vorne Links #######################################-->	
	<link name="left_front_wheel">
		<visual>
			<geometry>
				<mesh filename="package://volksbot_new/Media/original5.stl"/>			
			</geometry>
			<origin rpy="${pi/2} 0 0" xyz="0 0 0"/>
			<material name="black">
				<color rgba="0.1 0.1 0.1 1"/>
			</material>
		</visual>
		<collision>
			<geometry>
				<cylinder length="0.085" radius="0.13"/>
			</geometry>
			<origin rpy="${pi/2} 0 0" xyz="0 0 0"/>
		</collision>
		<inertial>
			<mass value="${mass_wheel}"/>
			<inertia ixx="0.0041" ixy="0.0" ixz="0.0" iyy="0.0041" iyz="0.0" izz="0.00718"/>
			<origin xyz="0 0 0" />
		</inertial>
	</link>

	<joint name="left_front_wheel_joint" type="continuous">
		<axis xyz="0 1 0"/>
		<parent link="base_link"/>
		<child link="left_front_wheel"/>
		<origin rpy="0 0 0" xyz="0.14 0.2075 0.13"/>
		<limit effort="100" velocity="100"/>
		<dynamics damping="0.0" friction="0.0"/>
	</joint>	
	<gazebo reference="left_front_wheel">
		<mu1 value="100"/>  
		<mu2 value="100"/> 
		<kp value="1000000.0"/>  
		<kd value="10000.0"/>    
		<fdir value="1 0 0"/>
		<friction value="100.0"/>  
		<material>Gazebo/Grey</material>
		<turnGravityOff>false</turnGravityOff>
	</gazebo>

<!-- #############################  Rad hinten Links  ######################################-->	
	<link name="left_back_wheel">
		<visual>
			<geometry>
				<mesh filename="package://volksbot_new/Media/original5.stl"/>			
			</geometry>
			<origin rpy="${pi/2} 0 0" xyz="0 0 0"/>
			<material name="black">
				<color rgba="0.1 0.1 0.1 1"/>
			</material>
		</visual>
		<collision>
			<geometry>
				<cylinder length="0.085" radius="0.13"/> 	
			</geometry>
			<origin rpy="${pi/2} 0 0" xyz="0 0 0"/>
		</collision>
		<inertial>
			<mass value="${mass_wheel}"/>
			<inertia ixx="0.0041" ixy="0.0" ixz="0.0" iyy="0.0041" iyz="0.0" izz="0.00718"/>
			<origin xyz="0 0 0" />
		</inertial>
	</link>

	<joint name="left_back_wheel_joint" type="continuous">
		<axis xyz="0 1 0"/>
		<parent link="base_link"/>
		<child link="left_back_wheel"/>
		<origin rpy="0 0 0" xyz="-0.14 0.2075 0.13"/>
		<limit effort="100" velocity="100"/>
		<dynamics damping="0.0" friction="0.0"/>
	</joint>	
	<gazebo reference="left_back_wheel">
		<mu1 value="100"/>  // alte Werte 57
		<mu2 value="100"/> // 1.5
		<kp value="1000000.0"/>  // 1000000.0
		<kd value="10000.0"/>    // 1.0
		<fdir value="1 0 0"/>  // 1 0 0
		<friction value="100.0"/>
		<material>Gazebo/Grey</material>
		<turnGravityOff>false</turnGravityOff>
	</gazebo>	

<!--  #################################  camera  ########################################-->	
	<link name="platform">
		<visual>
			<geometry>
				<box size="0.01 0.01 0.01"/>				
			</geometry>
			<origin rpy="0 0 0" xyz="0 0 0"/>
			<material name="red">
				<color rgba="1 0 0 1"/>
			</material>
		</visual>
		<collision>
			<geometry>
				<box size="0.01 0.01 0.01"/>
			</geometry>
			<origin xyz="0 0 0"/>
		</collision>
		<inertial>
			<mass value="0.001"/>
			<inertia ixx=".0001" ixy="0.0" ixz="0.0" iyy=".0001" iyz="0.0" izz=".0001"/>
			<origin xyz="-0.2 0 -0.185" />
		</inertial>
	</link>
<!--position camera platform-->		
	<joint name="base_link_to_platform" type="fixed">
		<parent link="base_link"/>
		<child link="platform"/>
		<origin rpy="0 0.25 0" xyz="0.2 0 0.26"/>
	</joint>		

  <!-- Kinect frames and mounting (includes simulation) -->
  <joint name="base_camera_joint" type="fixed">
    <origin rpy="0 0 0" xyz="0 0 0.03"/>
    <parent link="platform"/>
    <child link="camera_link"/>
  </joint>
  <link name="camera_link">
    <inertial>
      <mass value="0.01"/>
      <origin xyz="-0.2 0 -0.185"/>
      <inertia ixx="0.001" ixy="0.0" ixz="0.0" iyy="0.001" iyz="0.0" izz="0.001"/>
    </inertial>
    <visual>
      <origin rpy="0 0 0" xyz=" 0 0 0 "/>
      <geometry>
        <mesh filename="package://volksbot_new/meshes/kinect.dae"/>
      </geometry>
    </visual>
    <collision>
      <origin rpy="0 0 0" xyz="0.0 0.0 0.0"/>
      <geometry>
        <box size="0.0730 .2760 0.0720"/>
      </geometry>
    </collision>
  </link>
  <joint name="camera_depth_joint" type="fixed">
    <origin rpy="0 0 0" xyz="0 0.018 0"/>
    <parent link="camera_link"/>
    <child link="camera_depth_frame"/>
  </joint>
  <link name="camera_depth_frame">
    <inertial>
      <mass value="0.01"/>
      <origin xyz="-0.2 0 -0.185"/>
      <inertia ixx="0.001" ixy="0.0" ixz="0.0" iyy="0.001" iyz="0.0" izz="0.001"/>
    </inertial>
  </link>
  <joint name="camera_depth_optical_joint" type="fixed">
    <origin rpy="-1.570795 0 -1.570795" xyz="0 0 0"/>
    <parent link="camera_depth_frame"/>
    <child link="camera_depth_optical_frame"/>
  </joint>
  <link name="camera_depth_optical_frame">
    <inertial>
      <mass value="0.001"/>
      <origin xyz="-0.2 0 -0.185"/>
      <inertia ixx="0.0001" ixy="0.0" ixz="0.0" iyy="0.0001" iyz="0.0" izz="0.0001"/>
    </inertial>
  </link>
  <joint name="camera_rgb_joint" type="fixed">
    <origin rpy="0 0 0" xyz="0 -0.005 0"/>
    <parent link="camera_link"/>
    <child link="camera_rgb_frame"/>
  </joint>
  <link name="camera_rgb_frame">
    <inertial>
      <mass value="0.001"/>
      <origin xyz="-0.2 0 -0.185"/>
      <inertia ixx="0.0001" ixy="0.0" ixz="0.0" iyy="0.0001" iyz="0.0" izz="0.0001"/>
    </inertial>
  </link>
  <joint name="camera_rgb_optical_joint" type="fixed">
    <origin rpy="-1.570795 0 -1.570795" xyz="0 0 0"/>
    <parent link="camera_rgb_frame"/>
    <child link="camera_rgb_optical_frame"/>
  </joint>
  <link name="camera_rgb_optical_frame">
    <inertial>
      <mass value="0.001"/>
      <origin xyz="-0.2 0 -0.185"/>
      <inertia ixx="0.0001" ixy="0.0" ixz="0.0" iyy="0.0001" iyz="0.0" izz="0.0001"/>
    </inertial>
  </link>
<!-- Kinect Einstellungen -->  
  <gazebo reference="camera_link">
    <sensor:camera name="camera">
      <imageFormat>R8G8B8</imageFormat>
      <imageSize>640 480</imageSize>
      <hfov>90</hfov>
      <nearClip>0.05</nearClip>
      <farClip>10</farClip>  // Std 3
      <updateRate>20</updateRate>
      <baseline>0.1</baseline>
      <controller:gazebo_ros_openni_kinect name="kinect_camera_controller" plugin="libgazebo_ros_openni_kinect.so">
	<cameraName>camera</cameraName>
        <alwaysOn>true</alwaysOn>
        <updateRate>20</updateRate>
        <imageTopicName>camera/image_raw</imageTopicName>
        <pointCloudTopicName>camera/depth/points</pointCloudTopicName>
        <cameraInfoTopicName>camera/camera_info</cameraInfoTopicName>
        <frameName>camera_depth_optical_frame</frameName>
	<CxPrime>0.0</CxPrime>
	<Cx>0.0</Cx>
	<Cy>0.0</Cy>
	<focalLength>320.000101</focalLength>
	<hackBaseline>0.0</hackBaseline>
        <distortionK1>0.0</distortionK1>
        <distortionK2>0.0</distortionK2>
        <distortionK3>0.0</distortionK3>
        <distortionT1>0.0</distortionT1>
        <distortionT2>0.0</distortionT2>
      </controller:gazebo_ros_openni_kinect>
    </sensor:camera>
  </gazebo>

<!--  ###############################  laser ######################################### -->	
	<link name="roll_tilt_base">
		<visual>
			<geometry>
				<box size="0.001 0.001 0.001"/>				
			</geometry>
			<origin rpy="0 0 0" xyz="0 0 0"/>
		</visual>
	<!--	<collision>
			<geometry>
				<box size="0.001 0.001 0.001"/>
			</geometry>
			<origin xyz="0 0 0"/>
		</collision>-->
		<inertial>
			<mass value="0.01"/>
			<inertia ixx=".001" ixy="0.0" ixz="0.0" iyy=".001" iyz="0.0" izz=".001"/>
			<origin xyz="0 0 0.0" />
		</inertial>
	</link>
	<joint name="base_link_to_roll_tilt_base" type="continuous">   <!--revolute-->
		<parent link="base_link"/>
		<child link="roll_tilt_base"/>
		 <axis xyz="1 0 0"/>
		 <!--<limit effort="1000.0" lower="0.0" upper="0.548" velocity="0.5"/>-->
		<origin rpy="0 0 0" xyz="0 0 0.405"/>
	</joint>
	
	<link name="laser_platform">
		<visual>
			<geometry>
				<box size="0.01 0.01 0.01"/>				
			</geometry>
			<origin rpy="0 0 0" xyz="0 0 0"/>
			<material name="blue">
				<color rgba="0 0 1 1"/>
			</material>
		</visual>
		<collision>
			<geometry>
				<box size="0.01 0.01 0.01"/>
			</geometry>
			<origin xyz="0 0 0"/>
		</collision>
		<inertial>
			<mass value="0.001"/>
			<inertia ixx=".001" ixy="0.0" ixz="0.0" iyy=".001" iyz="0.0" izz=".001"/>
			<origin xyz="0 0 -0.33" />
		</inertial>
	</link>
<!--position laser_platform-->		
	<joint name="roll_tilt_base_to_laser_platform" type="continuous">   <!--revolute-->
	<!--<joint name="base_link_to_laser_platform" type="fixed">-->
		<parent link="roll_tilt_base"/>
		<child link="laser_platform"/>
		 <axis xyz="0 1 0"/>
		 <!--<limit effort="1000.0" lower="0.0" upper="0.548" velocity="0.5"/>-->
		<origin rpy="0 0 0" xyz="0 0 0"/>
	</joint>	
	<gazebo reference="platform">
		<material>Gazebo/Blue</material>
		<turnGravityOff>false</turnGravityOff>
	</gazebo>

  <!-- BASE LASER ATTACHMENT -->
  <joint name="laser_base_mount_joint" type="fixed">
    <origin rpy="0 0 0" xyz="0 0 0"/>
    <parent link="laser_platform"/>
    <child link="laser_base_link"/>
  </joint>
  
  
  <link name="laser_base_link" type="fixed">
    <inertial>
      <mass value="0.1"/>
      <origin xyz="0 0 -0.33"/>
      <inertia ixx="0.1" ixy="0" ixz="0" iyy="0.1" iyz="0" izz="0.1"/>
    </inertial>
    <visual>
      <origin rpy="0 0 0" xyz="0 0 0.025"/>
      <geometry>
        <box size="0.05 0.05 0.05"/>
      </geometry>
	<material name="blue">
		<color rgba="0 0 1 1"/>
	</material>
    </visual>
    <collision>
      <origin rpy="0 0 0" xyz="0 0 0.025"/>
      <geometry>
        <box size="0.05 0.05 0.05"/>
      </geometry>
    </collision>
  </link>
  <gazebo reference="laser_base_link">
    <material>Gazebo/Blue</material>
  </gazebo>
  <joint name="base_scan_joint" type="fixed">
    <origin rpy="0 0 0" xyz="0 0 0.05"/>
    <parent link="laser_base_link"/>
    <!--<child link="base_scan_link"/>-->
    <child link="laser"/>
  </joint>
  <!--<link name="base_scan_link" type="laser">-->
  <link name="laser" type="laser">
    <inertial>
      <mass value="0.1"/>
      <origin xyz="0 0 -0.33"/>
      <inertia ixx="0.1" ixy="0" ixz="0" iyy="0.1" iyz="0" izz="0.1"/>
    </inertial>
    <visual>
      <origin rpy="0 0 0" xyz="0 0 0.014"/>
      <geometry>
        <cylinder length="0.028" radius="0.0229"/>
      </geometry>
    </visual>
    <collision>
      <origin rpy="0 0 0" xyz="0 0 0.014"/>
      <geometry>
        <cylinder length="0.028" radius="0.0229"/>
      </geometry>
    </collision>
  </link> 
  <!--<gazebo reference="base_scan_link">-->
  <gazebo reference="laser">
    <material>Gazebo/Black</material>
  </gazebo>

<!--Laserscanner Einstellungen--> 
  <!--<gazebo reference="base_scan_link">-->
  <gazebo reference="laser">
    <sensor:ray name="laser">
      <rayCount>683</rayCount>
      <rangeCount>683</rangeCount>
      <laserCount>1</laserCount>
      <origin>0.0 0.0 0.0</origin>
      <displayRays>false</displayRays>
      <minAngle>-135</minAngle>
      <maxAngle> 135</maxAngle>
      <minRange>0.06</minRange>
      <maxRange>12.0</maxRange>
      <resRange>0.001</resRange>
      <updateRate>10.0</updateRate>
      <controller:gazebo_ros_laser name="gazebo_ros_base_scan_link_controller" plugin="libgazebo_ros_laser.so">
	<hokuyoMinIntensity>101.000000</hokuyoMinIntensity>
        <gaussianNoise>0.005</gaussianNoise>
        <alwaysOn>true</alwaysOn>
        <updateRate>10.0</updateRate>
        <topicName>base_scan/scan</topicName>
        <frameName>base_scan_link</frameName>
        <interface:laser name="gazebo_ros_base_scan_link_iface"/>
      </controller:gazebo_ros_laser>
    </sensor:ray>
  </gazebo>

<!--  ############################  Husky Controller Fuerte  ###################################-->	
<gazebo>
			<controller:husky_plugin name="husky_diff_controller" plugin="libhusky_description_new.so">
				<!--<controller:husky_plugin name="husky_diff_controller" plugin="libhusky_description_new_exp.so">-->
		        <alwaysOn>true</alwaysOn>
		        <updateRate>100.0</updateRate>  <!-- alt 100 -->
		        <backLeftJoint>left_back_wheel_joint</backLeftJoint>
		        <backRightJoint>right_back_wheel_joint</backRightJoint>
		        <frontLeftJoint>left_front_wheel_joint</frontLeftJoint>
		        <frontRightJoint>right_front_wheel_joint</frontRightJoint>
		        <wheelSeparation>0.445</wheelSeparation>
		        <wheelDiameter>0.26</wheelDiameter>
		        <torque>6</torque>  <!--24 alt  24/4 = 6.0-->
        </controller:husky_plugin>
	</gazebo> 

<!-- ######################### Laser Level Controller ##################################### -->
 <gazebo>   
    <controller:laser_level_plugin name="laser_level_controller" plugin="libohm_gaz_laser_lev.so">
                <alwaysOn>true</alwaysOn>
                <updateRate>100.0</updateRate>  <!-- alt 100 -->
    </controller:laser_level_plugin>
</gazebo> 

  <!-- #################################### IMU SENSOR ################################### -->

  <joint name="imu_joint" type="fixed">
      <axis xyz="1 0 0"/> <!-- 0 1 0 -->
      <origin xyz="0 0 0.301"/>
      <parent link="base_link"/>
      <child link="imu_link"/>
  </joint>


  <link name="imu_link">
      <inertial>
        <mass value="0.001"/>
        <origin rpy="0 0 0" xyz="0 0 0"/>
        <inertia ixx="0.0001" ixy="0" ixz="0" iyy="0.000001" iyz="0" izz="0.0001"/>
      </inertial>
      <visual>
        <origin rpy="0 0 0" xyz="0 0 0"/>
        <geometry>
          <box size="0.001 0.001 0.001"/>
        </geometry>
      </visual>
      <collision>
        <origin rpy="0 0 0" xyz="0 0 0"/>
        <geometry>
          <box size=".001 .001 .001"/>
        </geometry>
      </collision>
  </link>


<!--  <gazebo>
    <controller:gazebo_ros_imu name="imu_controller" plugin="libgazebo_ros_imu.so">
      <alwaysOn>true</alwaysOn>
      <updateRate>50.0</updateRate>
      <bodyName>imu_link</bodyName>
      <topicName>imu_data</topicName>
      <gaussianNoise>2.89e-08</gaussianNoise>
      <xyzOffsets>0 0 0</xyzOffsets>
      <rpyOffsets>0 0 0</rpyOffsets>
      <interface:position name="imu_position"/>
    </controller:gazebo_ros_imu>
  </gazebo>-->

<!-- ################################ 3D Odometrie ###################################################### -->
<!--
<gazebo>
	<controller:viso name="viso2" plugin="libviso2.so">
	<alwaysOn>true</alwaysOn>
	<updateRate>50.0</updateRate>
	<interface:position name="viso_position"/>
	</controller:viso>
<gazebo/>
-->

<!--  ############################## EchtzeitPlugin ###################################################### -->
<!--
<gazebo>
    <plugin name="gazebo_ros_controller_manager" filename="libgazebo_ros_controller_manager.so">
      <alwaysOn>true</alwaysOn>
      <updateRate>1000.0</updateRate>
    </plugin>
</gazebo>
-->
<!-- ######################################### PowerMonitor  ###############################################  -->
<!--
<gazebo>
    <plugin name="gazebo_ros_power_monitor_controller" filename="libgazebo_ros_power_monitor.so">
      <alwaysOn>true</alwaysOn>
      <updateRate>1.0</updateRate>
      <timeout>5</timeout>
      <powerStateTopic>power_state</powerStateTopic>
      <powerStateRate>10.0</powerStateRate>
      <fullChargeCapacity>87.78</fullChargeCapacity>
      <dischargeRate>-474</dischargeRate>
      <chargeRate>525</chargeRate>
      <dischargeVoltage>15.52</dischargeVoltage>
      <chargeVoltage>16.41</chargeVoltage>
    </plugin>
  </gazebo>
-->
</robot>
