<?xml version="1.0"?>
<robot name="Volksbot"
	xmlns:xi="http://www.w3.org/2001/XInclude"
	xmlns:gazebo="http://playerstage.sourceforge.net/gazebo/xmlschema/#gz"
	xmlns:model="http://playerstage.sourceforge.net/gazebo/xmlschema/#model"
	xmlns:sensor="http://playerstage.sourceforge.net/gazebo/xmlschema/#sensor"
	xmlns:body="http://playerstage.sourceforge.net/gazebo/xmlschema/#body"
	xmlns:geom="http://playerstage.sourceforge.net/gazebo/xmlschema/#geom"
	xmlns:joint="http://playerstage.sourceforge.net/gazebo/xmlschema/#joint"
	xmlns:controller="http://playerstage.sourceforge.net/gazebo/xmlschema/#controller"
	xmlns:interface="http://playerstage.sourceforge.net/gazebo/xmlschema/#interface"
	xmlns:rendering="http://playerstage.sourceforge.net/gazebo/xmlschema/#rendering"
	xmlns:renderable="http://playerstage.sourceforge.net/gazebo/xmlschema/#renderable"
	xmlns:physics="http://playerstage.sourceforge.net/gazebo/xmlschema/#physics"
	xmlns:xacro="http://ros.org/wiki/xacro"
>

<!--Variable Pi definieren-->
<property name="pi" value="3.1415926535897931"/>
<property name="mass_base" value="25"/>
<property name="mass_wheel" value="0.75"/>

<!--base_footprint is a fictitious link(frame) that is on the ground right below base_link origin, navigation stack depends on this frame-->
	<link name="base_footprint">
		<visual>
			<geometry>
				<box size="0.001 0.001 0.001"/>				
			</geometry>
			<origin rpy="0 0 0" xyz="0 0 0"/>
		</visual>
		<collision>
			<geometry>
				<box size="0.001 0.001 0.001"/>
			</geometry>
			<origin xyz="0 0 0"/>
		</collision>
		<inertial>
			<mass value="0.0001"/>
			<inertia ixx="0.0001" ixy="0.0" ixz="0.0" iyy="0.0001" iyz="0.0" izz="0.0001"/>
			<origin xyz="0 0 0.0" />
		</inertial>
	</link>
	
<!--Main Body-->	
	<link name="base_link">
		<visual>
			<geometry>
				<box size="0.6 0.35 0.2"/>				
			</geometry>
			<origin rpy="0 0 0" xyz="0 0 0"/>
			<material name="blue">
				<color rgba="0 0 .8 1"/>
			</material>
		</visual>
		<collision>
			<geometry>
				<box size="0.6 0.35 0.2"/>
			</geometry>
			<origin xyz="0 0 0"/>
		</collision>
		<inertial>
			<mass value="${mass_base}"/>
			<inertia ixx="0.83333" ixy="0.0" ixz="0.0" iyy="1.0052" iyz="0.0" izz="0.33854"/>
			<origin xyz="0 0 -0.1" />
		</inertial>
	</link>
	
<!--dummy joint-->	
	<joint name="base_footprint_joint" type="fixed">
		<parent link="base_footprint"/>
		<child link="base_link"/>
		<origin rpy="0 0 0" xyz="0 0 0"/>
	</joint>	
<!--camera platform-->	
	<link name="platform">
		<visual>
			<geometry>
				<box size="0.01 0.01 0.01"/>				
			</geometry>
			<origin rpy="0 0 0" xyz="0 0 0"/>
			<material name="red">
				<color rgba="0 0 .8 1"/>
			</material>
		</visual>
		<collision>
			<geometry>
				<box size="0.01 0.01 0.01"/>
			</geometry>
			<origin xyz="0 0 0"/>
		</collision>
		<inertial>
			<mass value="0.001"/>
			<inertia ixx="1.0" ixy="0.0" ixz="0.0" iyy="1.0" iyz="0.0" izz="1.0"/>
			<origin xyz="0 0 0.0" />
		</inertial>
	</link>
<!--position camera platform-->		
	<joint name="base_link_to_platform" type="fixed">
		<parent link="base_link"/>
		<child link="platform"/>
		<origin rpy="0 0.25 0" xyz="0.25 0 0.15"/>
	</joint>		

<!--laser_platform-->	
	<link name="laser_platform">
		<visual>
			<geometry>
				<box size="0.01 0.01 0.01"/>				
			</geometry>
			<origin rpy="0 0 0" xyz="0 0 0"/>
			<material name="red">
				<color rgba="0 0 .8 1"/>
			</material>
		</visual>
		<collision>
			<geometry>
				<box size="0.01 0.01 0.01"/>
			</geometry>
			<origin xyz="0 0 0"/>
		</collision>
		<inertial>
			<mass value="0.001"/>
			<inertia ixx="1.0" ixy="0.0" ixz="0.0" iyy="1.0" iyz="0.0" izz="1.0"/>
			<origin xyz="0 0 0.0" />
		</inertial>
	</link>
<!--position laser_platform-->		
	<joint name="base_link_to_laser_platform" type="fixed">
		<parent link="base_link"/>
		<child link="laser_platform"/>
		<origin rpy="0 0 0" xyz="0 0 0.33"/>
	</joint>	
	
<!--Rad vorne Rechts-->	
	<link name="right_front_wheel">
		<visual>
			<geometry>
				<cylinder length="0.08" radius="0.125"/>			
			</geometry>
			<origin rpy="${pi/2} 0 0" xyz="0 0 0"/>
			<material name="green">
				<color rgba="0 0.8 0 1"/>
			</material>
		</visual>
		<collision>
			<geometry>
				<cylinder length="0.08" radius="0.125"/>
			</geometry>
			<origin rpy="${pi/2} 0 0" xyz="0 0 0"/>
		</collision>
		<inertial>
			<mass value="${mass_wheel}"/>
			<inertia ixx="0.0033" ixy="0.0" ixz="0.0" iyy="0.0033" iyz="0.0" izz="0.00586"/>
			<origin xyz="0 0 0.0" />
		</inertial>
	</link>

	<joint name="right_front_wheel_joint" type="continuous">
		<axis xyz="0 1 0"/>
		<parent link="base_link"/>
		<child link="right_front_wheel"/>
		<origin rpy="0 0 0" xyz="0.16 -0.22 -0.045"/>
		<limit effort="100" velocity="100"/>
		<dynamics damping="0.0" friction="0.0"/>
	</joint>
<!--Rad hinten Rechts-->		
	<link name="right_back_wheel">
		<visual>
			<geometry>
				<cylinder length="0.08" radius="0.125"/>			
			</geometry>
			<origin rpy="${pi/2} 0 0" xyz="0 0 0"/>
			<material name="green">
				<color rgba="0 0.8 0 1"/>
			</material>
		</visual>
		<collision>
			<geometry>
				<cylinder length="0.08" radius="0.125"/>
			</geometry>
			<origin rpy="${pi/2} 0 0" xyz="0 0 0"/>
		</collision>
		<inertial>
			<mass value="${mass_wheel}"/>
			<inertia ixx="0.0033" ixy="0.0" ixz="0.0" iyy="0.0033" iyz="0.0" izz="0.00586"/>
			<origin xyz="0 0 0.0" />
		</inertial>
	</link>

	<joint name="right_back_wheel_joint" type="continuous">
		<axis xyz="0 1 0"/>
		<parent link="base_link"/>
		<child link="right_back_wheel"/>
		<origin rpy="0 0 0" xyz="-0.14 -0.22 -0.045"/>
		<limit effort="100" velocity="100"/>
		<dynamics damping="0.0" friction="0.0"/>
	</joint>
<!--Rad vorne Links-->	
	<link name="left_front_wheel">
		<visual>
			<geometry>
				<cylinder length="0.08" radius="0.125"/>			
			</geometry>
			<origin rpy="${pi/2} 0 0" xyz="0 0 0"/>
			<material name="green">
				<color rgba="0 0.8 0 1"/>
			</material>
		</visual>
		<collision>
			<geometry>
				<cylinder length="0.08" radius="0.125"/>
			</geometry>
			<origin rpy="${pi/2} 0 0" xyz="0 0 0"/>
		</collision>
		<inertial>
			<mass value="${mass_wheel}"/>
			<inertia ixx="0.0033" ixy="0.0" ixz="0.0" iyy="0.0033" iyz="0.0" izz="0.00586"/>
			<origin xyz="0 0 0.0" />
		</inertial>
	</link>

	<joint name="left_front_wheel_joint" type="continuous">
		<axis xyz="0 1 0"/>
		<parent link="base_link"/>
		<child link="left_front_wheel"/>
		<origin rpy="0 0 0" xyz="0.16 0.22 -0.045"/>
		<limit effort="100" velocity="100"/>
		<dynamics damping="0.0" friction="0.0"/>
	</joint>	

<!--Rad hinten Links-->	
	<link name="left_back_wheel">
		<visual>
			<geometry>
				<cylinder length="0.08" radius="0.125"/>			
			</geometry>
			<origin rpy="${pi/2} 0 0" xyz="0 0 0"/>
			<material name="green">
				<color rgba="0 0.8 0 1"/>
			</material>
		</visual>
		<collision>
			<geometry>
				<cylinder length="0.08" radius="0.125"/>	
			</geometry>
			<origin rpy="${pi/2} 0 0" xyz="0 0 0"/>
		</collision>
		<inertial>
			<mass value="${mass_wheel}"/>
			<inertia ixx="0.0033" ixy="0.0" ixz="0.0" iyy="0.0033" iyz="0.0" izz="0.00586"/>
			<origin xyz="0 0 0.0" />
		</inertial>
	</link>

	<joint name="left_back_wheel_joint" type="continuous">
		<axis xyz="0 1 0"/>
		<parent link="base_link"/>
		<child link="left_back_wheel"/>
		<origin rpy="0 0 0" xyz="-0.14 0.22 -0.045"/>
		<limit effort="100" velocity="100"/>
		<dynamics damping="0.0" friction="0.0"/>
	</joint>	
	
  <!-- Kinect frames and mounting (includes simulation) -->
  <joint name="base_camera_joint" type="fixed">
    <origin rpy="0 0 0" xyz="0 0 0.03"/>
    <parent link="platform"/>
    <child link="camera_link"/>
  </joint>
  <link name="camera_link">
    <inertial>
      <mass value="0.01"/>
      <origin xyz="0 0 0"/>
      <inertia ixx="0.001" ixy="0.0" ixz="0.0" iyy="0.001" iyz="0.0" izz="0.001"/>
    </inertial>
    <visual>
      <origin rpy="0 0 0" xyz=" 0 0 0 "/>
      <geometry>
        <mesh filename="package://volksbot_new/meshes/kinect.dae"/>
      </geometry>
    </visual>
    <collision>
      <origin rpy="0 0 0" xyz="0.0 0.0 0.0"/>
      <geometry>
        <box size="0.0730 .2760 0.0720"/>
      </geometry>
    </collision>
  </link>
  <joint name="camera_depth_joint" type="fixed">
    <origin rpy="0 0 0" xyz="0 0.018 0"/>
    <parent link="camera_link"/>
    <child link="camera_depth_frame"/>
  </joint>
  <link name="camera_depth_frame">
    <inertial>
      <mass value="0.01"/>
      <origin xyz="0 0 0"/>
      <inertia ixx="0.001" ixy="0.0" ixz="0.0" iyy="0.001" iyz="0.0" izz="0.001"/>
    </inertial>
  </link>
  <joint name="camera_depth_optical_joint" type="fixed">
    <origin rpy="-1.570795 0 -1.570795" xyz="0 0 0"/>
    <parent link="camera_depth_frame"/>
    <child link="camera_depth_optical_frame"/>
  </joint>
  <link name="camera_depth_optical_frame">
    <inertial>
      <mass value="0.001"/>
      <origin xyz="0 0 0"/>
      <inertia ixx="0.0001" ixy="0.0" ixz="0.0" iyy="0.0001" iyz="0.0" izz="0.0001"/>
    </inertial>
  </link>
  <joint name="camera_rgb_joint" type="fixed">
    <origin rpy="0 0 0" xyz="0 -0.005 0"/>
    <parent link="camera_link"/>
    <child link="camera_rgb_frame"/>
  </joint>
  <link name="camera_rgb_frame">
    <inertial>
      <mass value="0.001"/>
      <origin xyz="0 0 0"/>
      <inertia ixx="0.0001" ixy="0.0" ixz="0.0" iyy="0.0001" iyz="0.0" izz="0.0001"/>
    </inertial>
  </link>
  <joint name="camera_rgb_optical_joint" type="fixed">
    <origin rpy="-1.570795 0 -1.570795" xyz="0 0 0"/>
    <parent link="camera_rgb_frame"/>
    <child link="camera_rgb_optical_frame"/>
  </joint>
  <link name="camera_rgb_optical_frame">
    <inertial>
      <mass value="0.001"/>
      <origin xyz="0 0 0"/>
      <inertia ixx="0.0001" ixy="0.0" ixz="0.0" iyy="0.0001" iyz="0.0" izz="0.0001"/>
    </inertial>
  </link>
<!-- Kinect Einstellungen -->  
  <gazebo reference="camera_link">
    <sensor:camera name="camera">
      <imageFormat>R8G8B8</imageFormat>
      <imageSize>640 480</imageSize>
      <hfov>60</hfov>
      <nearClip>0.05</nearClip>
      <farClip>10</farClip>  // Std 3
      <updateRate>20</updateRate>
      <baseline>0.1</baseline>
      <controller:gazebo_ros_openni_kinect name="kinect_camera_controller" plugin="libgazebo_ros_openni_kinect.so">
        <alwaysOn>true</alwaysOn>
        <updateRate>20</updateRate>
        <imageTopicName>/camera/image_raw</imageTopicName>
        <pointCloudTopicName>/camera/depth/points</pointCloudTopicName>
        <cameraInfoTopicName>/camera/camera_info</cameraInfoTopicName>
        <frameName>camera_depth_optical_frame</frameName>
        <distortion_k1>0.0</distortion_k1>
        <distortion_k2>0.0</distortion_k2>
        <distortion_k3>0.0</distortion_k3>
        <distortion_t1>0.0</distortion_t1>
        <distortion_t2>0.0</distortion_t2>
      </controller:gazebo_ros_openni_kinect>
    </sensor:camera>
  </gazebo>

  <!-- BASE LASER ATTACHMENT -->
  <joint name="laser_base_mount_joint" type="fixed">
    <origin rpy="0 0 0" xyz="0 0 0"/>
    <parent link="laser_platform"/>
    <child link="laser_base_link"/>
  </joint>
  <link name="laser_base_link" type="fixed">
    <inertial>
      <mass value="0.1"/>
      <origin xyz="0 0 0.0"/>
      <inertia ixx="0.1" ixy="0" ixz="0" iyy="0.1" iyz="0" izz="0.1"/>
    </inertial>
    <visual>
      <origin rpy="0 0 0" xyz="0 0 0.025"/>
      <geometry>
        <box size="0.05 0.05 0.05"/>
      </geometry>
    </visual>
    <collision>
      <origin rpy="0 0 0" xyz="0 0 0.025"/>
      <geometry>
        <box size="0.05 0.05 0.05"/>
      </geometry>
    </collision>
  </link>
  <joint name="base_scan_joint" type="fixed">
    <origin rpy="0 0 0" xyz="0 0 0.05"/>
    <parent link="laser_base_link"/>
    <child link="base_scan_link"/>
  </joint>
  <link name="base_scan_link" type="laser">
    <inertial>
      <mass value="0.1"/>
      <origin xyz="0 0 0.0"/>
      <inertia ixx="0.1" ixy="0" ixz="0" iyy="0.1" iyz="0" izz="0.1"/>
    </inertial>
    <visual>
      <origin rpy="0 0 0" xyz="0 0 0.014"/>
      <geometry>
        <cylinder length="0.028" radius="0.0229"/>
      </geometry>
    </visual>
    <collision>
      <origin rpy="0 0 0" xyz="0 0 0.014"/>
      <geometry>
        <cylinder length="0.028" radius="0.0229"/>
      </geometry>
    </collision>
  </link> 
<!--Laserscanner Einstellungen--> 
  <gazebo reference="base_scan_link">
    <sensor:ray name="laser">
      <rayCount>683</rayCount>
      <rangeCount>683</rangeCount>
      <laserCount>1</laserCount>
      <origin>0.0 0.0 0.0</origin>
      <displayRays>false</displayRays>
      <minAngle>-135</minAngle>
      <maxAngle> 135</maxAngle>
      <minRange>0.06</minRange>
      <maxRange>12.0</maxRange>
      <resRange>0.001</resRange>
      <updateRate>10.0</updateRate>
      <controller:gazebo_ros_laser name="gazebo_ros_base_scan_link_controller" plugin="libgazebo_ros_laser.so">
        <gaussianNoise>0.005</gaussianNoise>
        <alwaysOn>true</alwaysOn>
        <updateRate>10.0</updateRate>
        <topicName>base_scan/scan</topicName>
        <frameName>base_scan_link</frameName>
        <interface:laser name="gazebo_ros_base_scan_link_iface"/>
      </controller:gazebo_ros_laser>
    </sensor:ray>
  </gazebo>


<!--Gazebo Einstellungen fuer fuerte geaendert-->
<!--	<gazebo>
		<controller:gazebo_ros_time name="gazebo_ros_time" plugin="libgazebo_ros_time.so">
			<alwaysOn>true</alwaysOn>
			<updateRate>1000.0</updateRate>
			<interface:audio name="dummy_gazebo_ros_time_iface_should_not_be_here"/>
		</controller:gazebo_ros_time>
	</gazebo>
-->
<!--Husky Controller Fahren-->	
<!--	<gazebo>
		<controller:huskyA200_base_controller name="huskyA200_base_controller" plugin="/home/schwinghammer/ros_workspace/controller/lib/libhuskyA200_base_controller.so">
		        <alwaysOn>true</alwaysOn>
		        <update>100</update>
		        <updateRate>100.0</updateRate>
		        <backLeftJoint>right_back_wheel_joint</backLeftJoint>
		        <backRightJoint>left_back_wheel_joint</backRightJoint>
		        <frontLeftJoint>right_front_wheel_joint</frontLeftJoint>
		        <frontRightJoint>left_front_wheel_joint</frontRightJoint>
		        <wheelSeparation>0.44</wheelSeparation>
		        <wheelDiameter>0.25</wheelDiameter>
		        <torque>24</torque>
		        <interface:position name="position_iface_0"/>
		        <topicName>cmd_vel</topicName>
        	</controller:huskyA200_base_controller>
		<canonicalBody>base_footprint</canonicalBody>	
	</gazebo> 
-->
<!--Husky Controller Fuerte Controller V2012-->	
<gazebo>
			<controller:husky_plugin name="husky_diff_controller" plugin="libhusky_plugin2012.so.so">
		        <alwaysOn>true</alwaysOn>
		        <updateRate>100.0</updateRate>
		        <backLeftJoint>left_back_wheel_joint</backLeftJoint>
		        <backRightJoint>right_back_wheel_joint</backRightJoint>
		        <frontLeftJoint>left_front_wheel_joint</frontLeftJoint>
		        <frontRightJoint>right_front_wheel_joint</frontRightJoint>
		        <wheelSeparation>0.44</wheelSeparation>
		        <wheelDiameter>0.25</wheelDiameter>
		        <torque>24</torque>  
        </controller:husky_plugin>
	</gazebo> 


	<gazebo reference="base_link">
		<material>Gazebo/Blue</material>
		<turnGravityOff>false</turnGravityOff>
	</gazebo>
	
	<gazebo reference="platform">
		<material>Gazebo/Red</material>
		<turnGravityOff>false</turnGravityOff>
	</gazebo>
	
	<gazebo reference="right_front_wheel">
		<mu1 value="100"/>  
		<mu2 value="100"/> 
		<kp value="100000000.0"/>  
		<kd value="10000.0"/>    
		<fdir value="1 0 0"/>  
		<material>Gazebo/Green</material>
		<turnGravityOff>false</turnGravityOff>
	</gazebo>

	<gazebo reference="right_back_wheel">
		<mu1 value="100"/> 
		<mu2 value="100"/>
		<kp value="100000000.0"/>  
		<kd value="10000.0"/>    
		<fdir value="1 0 0"/>  
		<material>Gazebo/Green</material>
		<turnGravityOff>false</turnGravityOff>
	</gazebo>

	<gazebo reference="left_front_wheel">
		<mu1 value="100"/>  
		<mu2 value="100"/> 
		<kp value="100000000.0"/>  
		<kd value="10000.0"/>    
		<fdir value="1 0 0"/>  
		<material>Gazebo/Green</material>
		<turnGravityOff>false</turnGravityOff>
	</gazebo>
		
	<gazebo reference="left_back_wheel">
		<mu1 value="100"/>  // alte Werte 57
		<mu2 value="100"/> // 1.5
		<kp value="100000000.0"/>  // 1000000.0
		<kd value="10000.0"/>    // 1.0
		<fdir value="1 0 0"/>  // 1 0 0
		<material>Gazebo/Green</material>
		<turnGravityOff>false</turnGravityOff>
	</gazebo>
	
  <gazebo reference="laser_base_link">
    <material>Gazebo/Grey</material>
  </gazebo>
  <gazebo reference="base_scan_link">
    <material>Gazebo/Black</material>
  </gazebo>
	
</robot>
